 # 10장. 예외 처리

---



## 10.1 예외와 예외 클래스

---

오류의 종류

- 에러 : 컴퓨터 하드웨어의 오동작 또는 고장으로 인해 응용 프로그램 실행 오류가 발생하는 것.(개발자는 대처가 불가능)

- 예외 : 사용자의 잘못된 조작또는 개발자의 잘못된 코딩으로 인해 발생하는 프로그램 오류 (개발자는 예외 처리를 통해 오류를 처리 가능)



예외의 종류

- 일반 예외 : 컴파일러 체크 예외라고도 함. 자바 소스를 컴파일하는 과정에서 예외 처리 코드가 필요한지 검사. 예외 처리 코드가 없으면 발생
  - Exception을 상속받지만 Runtime Exception을 상속받지 않는 클래스.
- 실행 예외 : 컴파일하는 과정에서 예외 처리 코드를 검사하지 않는 예외
  - Runtime Exception을 상속받은 클래스.

=> 자바에서는 예외를 클래스로 관리하고 JVM은 예외가 발생하면 발생한 예외 클래스로 객체를 생성한다.

=> 모든 예외들은 java.lang.Exception 클래스를 상속받는다.



## 10.2 실행 예외

---

자바 컴파일러가 체크를 하지 않기 떄문에 오로지 개발자의 경험에 의해서 예외 처리 코드를 삽입해야 한다.

실행시 해당 예외가 발생하면 프로그램은 곧바로 종료가 된다.



### Null PointerException

- 객체 참조가 없는 null 값을 갖는 참조 변수로 객체 접근 연산자를 사용했을 경우 발생
  - 즉 객체가 없는 상태에서 객체를 사용하려 했을 때 발생

``` java
public class NullPointerExceptionExample{
    public static void main(String args[]){
        String data = null;
        System.out.println(data.toString());
    }        
}
//
Exception in thread "main" java.lang.NullPointerException
	at ch10.NullPointerExceptionExample.main(NullPointerExceptionExample.java:6)
```

=> data는 null값을 가지나 toString() 메소드를 호출해서 예외 발생



### ArrayIndexOutOfBoundsException

- 배열에서 인덱스 범위를 초과하여 사용할 경우 발생

```java
public class ArrayIndexOutOfBoundsExceptionExample{
    public static void main(String args[]){
        String data1 = args[0];
        String data2 = args[1];
        
        System.out.println("args[0]: " + data1);
        System.out.println("args[1]: " + data2);
    }
}
//
Exception in thread "main" java.lang.ArrayIndexOutOfBoundsException: 0
	at ch10.ArrayIndexOutOfBoundsExceptionExample.main(ArrayIndexOutOfBoundsExceptionExample.java:5)
```

=> 그냥 실행하면 실행 매개값이 없기 떄문에 예외가 발생한다.

=> 실행 매개값으로 두 개의 매개값을 주면 예외가 발생하지 않는다.



``` java
public class ArrayIndexOutOfBoundsExceptionExample{
    public static void main(String args[]){
        if(args.length == 2){
            String data1 = args[0];
            String data2 = args[1];
            System.out.println("args[0]: " + data1);
            System.out.println("args[1]: " + data2);
        }
        else{
            System.out.println("[실행 방법]");
            System.out.println("java ArrayIndexOutOfBoundsExceptionExample ");
            System.out.println("값1 값2");
        }
        
    }
}
```

=> 조건문을 이용해 배열의 길이를 먼저 알아봐주는 코드



### NumberFormatException

문자열로 되어있는 데이터를 숫자로 변경하는 코드

| 반환 타입 | 메소드명(매개 변수)          | 설명                                 |
| --------- | ---------------------------- | ------------------------------------ |
| int       | Integer.parseInt(String s)   | 주어진 문자열을 정수로 반환해서 리턴 |
| double    | Double.parseDouble(String s) | 주어진 문자열을 실수로 변환해서 리턴 |

- 숫자로 변경할 수 없는 문자가 포함되어있다면 예외가 발생

``` java
public class NumberFormatExceptionExample{
    public static void main(String args[]){
        String data1 = "100";
        String data2 = "a100";
        
        int value1 = Integer.parseInt(data1);
        int value2 = Integer.parseInt(data2);
        
        int result = value1 + value2;
        System.out.println(result);
    }
}
//
Exception in thread "main" java.lang.NumberFormatException: For input string: "a100"
	at java.lang.NumberFormatException.forInputString(NumberFormatException.java:65)
	at java.lang.Integer.parseInt(Integer.java:580)
	at java.lang.Integer.parseInt(Integer.java:615)
	at ch10.NumberFormatExceptionExample.main(NumberFormatExceptionExample.java:9)
```

=> value2 에서 숫자로 바꿀수 없는 문자열을 변환하려다 예외가 발생



### ClassCastException

- 클래스, 인터페이스에서 억지로 타입변환을 시도할 경우 발생

- 타입 변환전 instanceof 연산자를 사용하면 변환 가능한지 미리 확인할 수 있다.

``` java
public class ClassCatExceptionExample{
    public static void main(String args[]){
        Dog dog = new Dog();
        changeDog(dog);
        
        Cat cat = new Cat();
        changeDog(cat);
    }
    
    public static void changeDog(Animal animal){
    	// if(animal instanceof Dog){
        Dog dog = (Dog) animal;
        // }
    }
}

class Animal{}
class Dog extends Animal{}
class Cat extends Animal{}
//
java: class ClassCatExceptionExample is public, should be declared in a file named ClassCatExceptionExample.java
```

=> Cat 객체를 Dog타입으로 변환하려 함

=> // 부분의 instanceof 연산자를 사용해 예외를 막을 수 있음



## 10.3 예외 처리 코드

---

에외 처리 코드란? 

- 프로그램 예외가 발생했을 경우 프로그램의 갑작스러운 종료를 막고, 정상 실행을 유지할 수 있도록 처리하는 코드.

- try-catch-finally 구문을 사용한다.

정상 실행 되었을 경우

![image](C:\Users\user\Downloads\image.png)

예외가 발생되었을 경우

![image](C:\Users\user\Downloads\image (1).png)

try-catch-finally 구문의 실행

1. try 블록엔 예외 발생 가능 코드가 위치한다.

2. 예외 발생 없이 정상 실행시엔 finally 구문이 실행된다.
3. 만약 try 블록의 예외가 발생하면 catch블록으로 이동해서 예외 처리 코드를 실행한다.
4. 그 후에 finally 블록이 실행된다.
5. finally 블록은 생략이 가능하다.
6. fianlly 블록은 예외 발생 여부와 상관 없이 항상 실행된다!



일반 예외 처리

``` java
public class TryCatchFinallyExample{
    public static void main(String args[]){
        try{
            Class clazz = Class.forName("java.lang.String2");
        }
        catch(ClassNotFoundException e){
            System.out.println("클래스가 존재하지 않습니다.")
        }
    }
}
//
클래스가 존재하지 않습니다.
```

=> 4라인에서 ClassNotFoundException이 발생해 catch구문이 실행된다.



실행 예외 처리

``` java
public class TryCatchFinallyRuntimeExceptionExample{
    public static void main(String args[]){
        String data1 = null;
        String data2 = null;
        try{
            data1 = args[0];
            data2 = args[1];
        }
        catch(ArrayIndexOutOfBoundsException e){
            System.out.println("실행 매개값의 수가 부족합니다.");
            System.out.println("[실행 방법]");
            System.out.println("java TryCatchFinallyRuntimeExceptionExample num1 num2");
            return;
        }
        
        try{
            int value1 = Integer.parseInt(data1);
            int value2 = Integer.parseInt(data2);
            int result = value1 + value2;
            System.out.println(data1 + "+" + data2 + "=" + result);
        }
        catch(NumberFormatException e){
            System.out.println("숫자로 변환할 수 없습니다.");
        }
        finally{
            System.out.println("다시 실행하세요.");
        }
    }
}
//
실행 매개값의 수가 부족합니다.
[실행 방법]
java TryCatchFinallyRuntimeExceptionExample num1 num2

//
숫자로 변환할 수 없습니다.
다시 실행하세요.

//
10+20=30
다시 실행하세요.
```

=> 첫번째 실행 결과의 경우는 catch구문이 실행되고 return문으로 프로그램이 종료된다.

=> 두번째 실행 결과의 경우는 매개값의 값이 숫자가 아닌게 들어와 두번째 catch구문이 실행되고 finally구문이 실행된다.

=> 세번째 실행 결과의 경우는 두번째 try구문이 실행되고 finally 구문이 실행된다.



## 10.4 예외 종류에 따른 처리 코드

---

### 다중 catch

- try구문 내에서 여러가지 예외가 발생할 경우 예외별로 다른 예외처리를 위해 cath블록을 여러개 작성하는 것이 가능하다.!

- try블록에서 해당 타입의 예외가 발생하면 catch 블록이 실행하도록 되어 있다.

- catch 블록이 여러개 작성되어 있어도 한가지 catch 블록만이 실행된다.

``` java
public class CatchByExceptionKindExample{
    public static void main(String args[]){
        try{
            String data1 = args[0];
            String data2 = args[1];
            int value1 = Integer.parseInt(data1);
            int value2 = Integer.parseInt(data2);
            int result = value1 + value2;
            System.out.println(data1 + "+" + data2 + "=" + result);
        }catch(ArrayIndexOutOfBoundsException e){
            System.out.println("실행 매개값의 수가 부족합니다.");
            System.out.println("[실행 방법]");
            System.out.println("java CatchByExceptionKindExample num1 num2");
        }catch(NumberFormatException e){
            System.out.println("숫자로 변한할 수 없습니다.");
        }finally{
            System.out.println("다시 실행하세요.");
        }
    }
}
//
실행 매개값의 수가 부족합니다.
[실행 방법]
java CatchByExceptionKindExample num1 num2
다시 실행하세요.
```

=> 바로위 예제의 try catch 구문을 하나로 묶었다.



### catch 순서

다중 catch 블록을 작성할 때 주의할 점은 상위 예외 클래스가 하위 예외 클래스보다 아래쪽에 위치해야 한다!!

catch클래스는 위에서부터 차례대로 실행되기 때문에 상위 예외 클래스의 catch블록이 위에 있다면 하위 catch 블록은 실행되지 않기 떄문이다!

``` java
public class CatchOrderExample{
    public static void main(String args[]){
        try{
            String data1 = args[0];
            String data2 = args[1];
            int value1 = Integer.parseInt(data1);
            int value2 = Integer.parseInt(data2);
            int result = value1 + value2;
            System.out.println(data1 + "+" + data2 + "=" + result);
        }
        catch(ArrayIndexOutOfBoundsException e){
            System.out.println("실행 매개값의 수가 부족합니다.");
        }
        catch(Exception e){
            System.out.println("실행에 문제가 있습니다.");
        }
        finally {
            System.out.println("다시 실행하세요.");
        }
    }
}
```

=> Exception이 상위 예외기 때문에 Exception을 상속받는 ArrayIndexOutOfBoundsException의 catch 구문이 먼저 실행되게 작성하였다.



### 멀티 catch

- 자바 7 이후부터 추가된 기능이다.
- 하나의 catch블록에서 여러 개의 예외를 처리하는 기능이다.

``` java
public class CatchOrderExample{
    public static void main(String args[]){
        try{
            String data1 = args[0];
            String data2 = args[1];
            int value1 = Integer.parseInt(data1);
            int value2 = Integer.parseInt(data2);
            int result = value1 + value2;
            System.out.println(data1 + "+" + data2 + "=" + result);
        }
        catch(ArrayIndexOutOfBoundsException e | NumberFomatExeption e){
            System.out.println("실행 매개값의 수가 부족하거나 숫자로 변환할 수 없습니다.");
        }
        catch(Exception e){
            System.out.println("알수 없는 예외 발생");
        }
        finally {
            System.out.println("다시 실행하세요.");
        }
    }
}
```

=> ArrayIndexOutOfBoundsException과 NumberFomatExeption을 하나의 catch블록에서 동시에 처리



## 10.5 자동 리소스 닫기

---

- 자바 7이후부터 새로 추가됨.
- try-with-resources를 사용하면 예외 발생 여부와 상관없이 사용했던 리소스 객체(각종 입출력 스트림, 서버 소켓, 소켓, 각종 채널)의 close() 메소드르를 호출해서 안전하게 리소스를 닫아준다.  (-> 리소스란? 데이터를 읽고 쓰는 객체라고 알아두자.)

``` java
// 리소스 객체를 안전하게 닫기 위해 자바 6이전까지 사용해왔던 코드.
FileInputStream fis = null;
try{
    fis = new FileInputStream("file.txt");
    ...
}catch(IOException e){
    ...
}finally{ // finally 블록에서 try-catch를 사용해서 close()를 처리
    if (fis != null){
        try{
            fis.close();
        }catch(IOException e) {} 
    }
}
```

try-with-resources 를 사용하면

``` java
try(FileInputStream fis = new FileInputStream("file.txt")){
    ...
}catch(IOException e){
    ...
} // close()를 명시적으로 호출하지 않음.
```

- try 블록이 정상적으로 실행을 완료하거나 도중에 예외를 발생하게 되면 FileInputStream의 close() 메소드가 호출된다.
- try{}에서 예외가 발생하면 우선 close()로 리소스를 닫고 catch블록을 실행한다.

``` java
// 복수 개의 리소스를 사용해야 하는 경우.
try{
    FileInputStream fis = new FileInputStream("file1.txt");
    FileOutputStream fos = new FileOutputStream("file2.txt");
}{
    ...
}catch(IOException e){
    ...
}
```

try-with-resources의 사용 조건

- 리소스 객체는 java.lang.AutoCloseable인터페이스를 구현하고 있어야 해야함

  -> try-with-resources는 AutoCloseable의 close() 메소드를 자동으로 호출한다.



```java
public class FileInputStream implements AutoCloseable{
    private String file;
    
    public FileInputStream(String file){
        this.file = file;
    }
    
    public void read(){
        System.out.println(file + "을 읽습니다.");
    }
    
    @Override
    public void close() throws Exception{ 
        System.out.println(file + "을 닫습니다.");
    }
}
```

```java
public class TryWithResourceExample {
    public static void main(String[] args){
        try(FileInputStream fis = new FileInputStream("file.txt")){
            fis.read();;
            throw new Exception(); // 강제적으로 예외를 발생시킴.
        }catch (Exception e){
            System.out.println("예외 처리 코드가 실행되었습니다.");
        }
    }
}
//
file.txt을 읽습니다.
file.txt을 닫습니다.
예외 처리 코드가 실행되었습니다.
```



## 10.6 예외 떠넘기기

---

메소드 내부에서 예외가 발생할 수 있는 코드를 작성할 때 메소드를 호출한 곳으로 예외를 떠넘길 수도 있다.

throws키워드의 사용

```java
리턴타입 메소드명(매개변수, ...)throws 예외클래스1, 예외클래스2, ... {
    
}
```

-> throws Exception을 사용해 모든 예외를 떠넘길 수도 있다.

``` java
리턴타입 메소드명(매개변수, ...) throws Exception{
    
}
```

- throws 키워드가 붙어있는 메소드는 반드시 try 블록 내에서 호출되어야 한다.
- 그리고 catch블록에서 떠넘겨 받은 예외를 처리해야 한다.



ex) thrwos 키워드가 있는 method2()를 method1()에서 호출하는 방법

``` java
public void method1(){
    try{
        method2();
    }catch(ClassNotFoundException e){
        // 예외 처리 코드
        System.out.println("클래스가 존재하지 않습니다.")
    }
}

public void method2() throws ClassNotFoundException {
    Class clazz = Class.forName("java.lang.String2");
}
```

method1()에서도 아래처럼 throws 키워드로 다시 예외를 떠넘길 수 있다.

```java
public void method1() throws ClassNotFoundException{
    method2();
}
```



``` java
public class ThrowsExample{
    public static void main(String args[]){
        try{
            findClass();
    	}
    	catch(ClassNotFoundException e){ // 예외를 처리했다.
        	System.out.println("클래스가 존재하지 않습니다.");
    	}
	}

	public static void findClass() throws ClassNotFoundException{ // findClass() 메소드가 예외를 떠넘기고
    	Class clazz = Class.forName("java.lang.String2");
    }
}
//
클래스가 존재하지 않습니다.
```

main() 메소드에서도 throws 키워드로 예외를 떠넘길 수 있다

-> JVM이 최종적으로 예외 처리를 하게 된다. JVM은 예외의 내용을 콘솔에 출력하는 것으로 예외 처리를 한다.

``` java
public static void main(String[] args) throws classNotFoundException{
    findClass();
}
```

main() 메소드에서 throws Exception을 붙이는 것은 프로그램이 알 수 없는 예외 내용을 출력하고 종료되므로 좋지 않다.

-> main()에서 try-catch 블록으로 예외를 최종처리하자.!

## 10.7 사용자 정의 예외와 예외 발생

---

### 사용자 정의 예외 클래스 선언

컴파일러가 체크하는 일반 예외 - Exception을 상속

컴파일러가 체크하지 않는 실행 예외 - RuntimeException을 상속

``` java
public class XXXException extends [ Exception | RuntimeException ]{
    public XXXException(){}
    public XXXException(String message){super(message);}
}
```

- 사용자 정의 예외 클래스 이름은 Exception으로 끝나는 것이 좋다.
- 사용자 정의 에외 클래스도 필드, 생성자, 메소드 선언을 포함할 수 있으나 보통 생성자 선언만을 포함한다.
- 생성자는 두개를 선언하는 것이 일반적
  - 하나는 매개 변수가 없는 생성자
  - 다른 하나는 예외 발생 원인을 전달하기 위해 String 타입의 매개변수를 갖는 생성자

- String 타입의 매개 변수를 갖는 생성자는 상위클래스의 생성자를 호출하여 예외 메세지를 넘겨준다.

``` java
public class BalanceInsufficientException extends Exception{
    public BalanceInsufficientException(){}
    public BalanceInsufficientException(String message){
        super(message);
    }
}
```

=> BalanceInsufficientException는 Exception을 상속하기 때문에 컴파일러가 체크하는 일반예외 -> try-catch 블록으로 예외 처리가 필요하다.



### 예외 발생시키기

코드에서 예외를 발생시키는 방법

``` java
throws new XXXException();
throws new XXXException("메세지");
```

예외 객체를 생성할 때는 기본 생성자 또는 예외 메세지를 갖는 생성자 중 어떤 것을 사용해도 된다.

예외 발생 코드를 가지고 있는 메소드는 내부에서 try-catch 블록으로 예외를 처리할 수 있지만, 대부분은 자신을 호출한 곳에서 예외를 처리하도록 throws를 떠넘긴다.

``` java
public void method() throws XXXException{
    throw new XXXException("메세지");
}
```

``` java
try{
    method();
}
catch(XXXException e){
    //예외 처리
}
```



은행 계좌의 잔고가 부족하면 예외가 발생하도록 작성된 코드

``` java
public class Account{
    private long balance;
    
    public Account(){}
    
    public long getBalance(){
        return balance;
    }
    public void deposit(int money){
        balance += money;
    }
    public void withdraw(int money) throws BalanceInsufficientException{
        if(balance < money){
            throw new BalanceInsufficientException("잔고 부족: " + (money-balance) + "모자람"); // 사용자 정의 예외 발생.
        }
        balance -= money;
    }
}
//
예금액: 10000
잔고 부족: 20000모자람

ch10.BalanceInsufficientException: 잔고 부족: 20000모자람
	at ch10.Account.withdraw(Account.java:16)
	at ch10.AccountExample.main(AccountExample.java:11)
```



## 10.8 예외 정보 얻기

---

try 블록에서 예외가 발생되면 예외 객체는 catch 블록의 매개 변수에서 참조하게 되므르 매개 변수를 이용하면 예외 객체의 정보를 알 수 있다.

예외를 발생 시킬 때 String 타입의 메세지를 갖는 생성자를 이용하였다면, 메세지는 자동으로 객체 내부에 저장이된다.

``` java
throw new XXXException("예외 메세지");
```

예외 메세지는 catch 블록에서 getMessage() 메소드릐 리턴값으로 얻을 수 있다.

``` java
catch(Exception e){
    String message = e.getMessage();
}
```

=>

``` java
try{
    
    
}
catch(예외클래스 e ){
    // 예외가 가지고 있는 Message얻기
    String message = e.getMessage();
    
    // 예외의 발생 경로를 추적
    e.printStackTrace();
}
```



``` java
public class AccountExample{
    public static void main(String args[]){
        Account account = new Account();

        account.deposit(10000);
        System.out.println("예금액: " + account.getBalance());

        try{
            account.withdraw(30000);
        }
        catch(BalanceInsufficientException e){ // 예외 메세지 얻기
            String message = e.getMessage();
            System.out.println(message); // 예외 추적 후 출력
            System.out.println();
            e.printStackTrace();
        }
    }
}
//
예금액: 10000
잔고 부족: 20000모자람

ch10.BalanceInsufficientException: 잔고 부족: 20000모자람
	at ch10.Account.withdraw(Account.java:16)
	at ch10.AccountExample.main(AccountExample.java:11)
```



